Workbook

Sheet Audit Tool
A1: CQC KLOE | B1: Section | C1: Audit Criteria | D1: Evidence Seen | E1: Compliant (Y/N) | F1: RAG | G1: CommentsActions / Recommendations | H1: Responsible Person | I1: Target Date
A2: WELL-LED | B2: Team Meetings & Staff Conduct | C2: Meeting frequency, attendance, minutes | D2: Team meetings are held monthly; however, actions from previous meetings must be reviewed at the start of each meeting. This was not referenced in the last three sets of minutes reviewed. Please ensure the correct meeting template (available on Atlas) is used, as it contains a set agenda that you can add to and ensures actions are consistently reviewed. | E2: No | F2: Amber | G2: Use the correct staff meeting template and include a review of previous meeting actions as the first agenda item going forward. | I2: 46112
A3: WELL-LED | B3: Team Meetings & Staff Conduct | C3: Staff on suspension / disciplinary / improvement plans (number) | D3: None | E3: Yes | F3: Green
A4: WELL-LED | B4: Staffing Overview | C4: All staff wear Filey Care uniforms and are presentable, including appropriate footwear. | D4: All staff were wearing uniforms, suitable footwear, and were presentable on the day of the visit. | E4: Yes | F4: Green
A5: WELL-LED | B5: Staffing Overview | C5: The staff-to-service-user ratio is appropriate to cover both core hours and one-to-one support. | D5: Staffing levels were compliant on the day of the visit, with two support workers and one manager on shift supporting four service users. | E5: Yes | F5: Green
A6: WELL-LED | B6: Staffing Overview | C6: Current agency staff in use (number & reason) | D6: None | E6: Yes | F6: Green
A7: WELL-LED | B7: Staffing Overview | C7: Induction process for agency staff | D7: Induction process is completed by HR and then reviewed by the line manager. | E7: Yes | F7: Green
A8: WELL-LED | B8: Staffing Overview | C8: Overall sickness level (including long-term) | D8: No staff members are currently off sick | E8: Yes | F8: Green
A9: WELL-LED | B9: Staffing Overview | C9: Staff retention & vacancies | D9: Staff retention is good | E9: Yes | F9: Green
A10: WELL-LED | B10: Staffing Overview | C10: Supervision frequency & outcomes (Supervision Matrix) | D10: Supervision is conducted quarterly. The supervision matrix was reviewed and provided clear evidence that supervisions are being completed as required. | E10: Yes | F10: Green
A11: WELL-LED | B11: Staffing Overview | C11: Appraisal process | D11: Appraisals are conducted annually. Dates are recorded on the supervision matrix, with the next due dates clearly inputted. | E11: Yes | F11: Green
A12: EFFECTIVE | B12: Training & Competency | C12: Mandatory training compliance (online, face to face, virtual) Training matrix provided and up to date | D12: After viewing the training matrix on Atlas it appears that all staff are in date with their training and up to date.
A13: EFFECTIVE | B13: Training & Competency | C13: Qualifications & Training Compliance Included in this section: Qualifications (certificates) Mandatory Training Record/Matrix Specialist Training Certificates Medication Competence Assessment Shadowing & Feedback Form | D13: Mandatory training records and specialist training certificates were present for all staff. Medication competence assessments are completed for all except: Michael Adegborioye: Medication Competence Assessment was present but expired (10/03/25) and therefore out of date; refresher required. Shadowing & feedback forms were present for all staff, confirming observation‑based competency at induction.
A14: EFFECTIVE | B14: Training & Competency | C14: Identified training needs and timescales
A15: WELL-LED | B15: Recruitment & Staff Files | C15: Safer Recruitment Documentation Included in this section: Application form CV Interview questionnaire Offer letter Right to Work documentation (where applicable) Proof of ID Two proofs of address & verification Employment contract Two staff references DBS certificate Job Description Secondary Employment Declaration Staff Consent to Working Hours | D15: Evidence across all five staff files reviewed shows that safer recruitment documentation is largely in place and compliant. Application forms, CVs, interview records, offer letters, Right to Work (where relevant), DBS certificates, ID checks, address verification, and employment contracts were all present. Reference Requirements: Two staff members (Michael A. and Emmanuel O.) each had only one reference in file. This is due to their long tenure and historical processes prior to the updated HR requirement. Both files now include an explanation in the HR documentation, and the updated HR process mandates two references for all new starters going forward.
A16: WELL-LED | B16: Recruitment & Staff Files | C16: Induction Records & Employment Documentation Included in this section: Induction Checklist Staff Handbook Probation Form / Confirmation Letter Bank Details (admin/HR requirement, not regulatory) | D16: All staff files contained a completed Induction Checklist and signed Staff Handbook. Probation forms and confirmation letters were present for all relevant staff, demonstrating completion of the induction period and employer sign‑off.
A17: WELL-LED | B17: Recruitment & Staff Files | C17: Ongoing Performance Monitoring Included in this section: Supervisions Appraisals Spot Checks | D17: Supervision records were present for all staff. Appraisal documentation was present for all except: Michael Adegborioye: Appraisal not found. Spot checks had been completed on: Emmanuel Kwarteng – 03/02/26 Emmanuel Odejide – 12/01/26 Izuchukuwu Paul Okeke – 13/03/26 These spot checks confirm ongoing oversight and good management visibility across the workforce.
A18: WELL-LED | B18: Recruitment & Staff Files | C18: Any other documents | D18: Not applicable
A19: CARING | B19: People & Wellbeing | C19: Support plans reviewed regularly Person centred?
A20: CARING | B20: People & Wellbeing | C20: Mental Capacity Assessments (decision-specific) | D20: Not all MCA2s were completed on Cura. Examples of completed MCA templates were provided to the manager to support accurate completion going forward. | E20: Yes | F20: Green | G20: Manager to complete all outstanding MCA2s on Cura and ensure all future MCA2s are accurately recorded using the correct template. Action has now been completed. | H20: Michael | I20: 46105
A21: CARING | B21: People & Wellbeing | C21: Court of Protection involvement / matrix LPA / Advocacy arrangements/OPG100 Form (Office of Public Guiding Application online) | D21: There are none in place. | E21: Yes | F21: Green
A22: CARING | B22: People & Wellbeing | C22: Risk assessments (e.g., additional r/a identified in support plans, diabetic, epilepsy, mental health, falls, self-harm, medication)
A23: CARING | B23: People & Wellbeing | C23: Daily notes – accurate, dated, signed, title of task/activity, duration of time recorded for each activity.
A24: CARING | B24: People & Wellbeing | C24: Monthly Progress Report (Sharing i.e. social workers, Care coordinator) Handovers (Recording/Communication
A25: CARING | B25: People & Wellbeing | C25: Service user involvement in planning and decision-making
A26: CARING | B26: People & Wellbeing | C26: Keyworker meetings | D26: Key worker sessions need to be more detailed and written in a more person‑centred way. The individual’s voice should be clearly reflected throughout. We must evidence that residents are actively involved in their sessions and are asked about their preferred activities and choices. | E26: Yes | F26: Amber
A27: CARING | B27: People & Wellbeing | C27: PEEPs with photographs in place | D27: PEEPS have been viewed in the service user files and the grab bag. | E27: Yes | F27: Green
A28: CARING | B28: People & Wellbeing | C28: End-of-life planning where relevant
A29: CARING | B29: People & Wellbeing | C29: Safe management of money and belongings
A30: CARING | B30: People & Wellbeing | C30: Secure storage of service user files | D30: Service users files are kept in a secure filing cabinet in the office. | E30: Yes | F30: Green
A31: SAFE | B31: Medication Support | C31: Medication storage | D31: Observed on the day of visit: Medication stored securely in a locked office cabinet. Individual boxes clearly labelled with service users’ names. Thermometer in place, reading maintained at 23°C. Daily temperature check recorded on checklist and up to date. | E31: Yes | F31: Green
A32: SAFE | B32: Medication Support | C32: MAR sheets / PRN protocols completed accurately | D32: MARs and PRN protocols were checked by the medication lead on a separate audit form. They were found to be accurate. statement from audit: "I worked there throughout the day, and Olivia was also present. I reviewed all service users’ medication care plans, PRN protocols, MAR charts, and care passports. I identified some inconsistencies and informed Michael and Olivia, which have now been corrected. More importantly, the service users’ files were re-arranged according to the updated format prepared by Helen. In addition, a separate medication master file containing all service users’ medication documents has been created." | E32: Yes | F32: Green
A33: SAFE | B33: Medication Support | C33: Stock checks / visual count match Controlled drugs (if applicable) | D33: The Medication Lead completes unannounced medication counts, providing an additional layer of oversight and compliance. The most recent unannounced count was completed on 09/03/2026, during which a small number of issues were identified. An action plan has been sent to Rivulet to address and rectify the issues found, and this is currently in progress. Daily medication stock counts are being completed consistently. These daily counts should be recorded in the Cura system, which is the organisation’s current digital method for medication tracking. However, during the visit, the provision was found to be using the older paper-based form, which was viewed on the day. The service was advised to transition to the Cura system for daily medication counts going forward to align with updated organisational processes. Compliance has not been compromised, as stock counts are being completed correctly regardless of whether they are recorded on paper or in Cura. | E33: Yes | F33: Green | G33: The service was advised to transition to the Cura system for daily medication counts going forward to align with updated organisational processes. | H33: Michael | I33: 46106
A34: SAFE | B34: Medication Support | C34: Covert medication / best interest decisions | D34: No covert medication in place. | E34: Yes | F34: Green
A35: SAFE | B35: Medication Support | C35: Medication error records and notifications | D35: Medication errors are managed in line with procedure. Incident reports are completed on Cura following any error. Further actions are taken depending on the nature and severity of the error (e.g., escalation, review, retraining). | E35: Yes | F35: Green
A36: SAFE | B36: Medication Support | C36: Medication competence assessments | D36: All staff medication competencies have been completed and verified. Competencies were viewed in staff files during the audit and found to be up to date. Competency status is tracked and monitored through the Supervision Matrix, which is overseen by HR and line managers to ensure ongoing compliance. No outstanding actions identified in this area. | E36: Yes | F36: Green
A37: SAFE | B37: Medication Support | C37: Fridge temperature checks and use | D37: Evidence was seen of a fridge temperature checklist displayed on the fridge and being completed daily. No medication is currently stored in the fridge, as this is not required for the medicines in use at present. | E37: Yes | F37: Green
A38: SAFE | B38: Medication Support | C38: Support for self-administration (assessed and documented)
A39: EFFECTIVE | B39: Nutrition & Health | C39: Food passport / pictorial menus. Including likes/dislikes. | D39: Each service user’s food preferences, including likes and dislikes, are recorded on their profile page within the Cura system. For RG, the following information is documented: • Likes: Pastries, toast with spread (butter),fries, Pasta, Pizza, red meat, rice with stewed grilled chicken, coffee, jerk chicken and Caribbean food.. • Dislikes:No dislikes in regards to food documented. RG’s weekly food planner on Cura is not completed as RG is independent with cooking and planning his meals, therefore is not a requirement. Within RG’s Nutrition Care Plan, it states: “I am able to shop for food and prepare meals for myself. However, there may be times when I need occasional reminders to plan meals or prepare food regularly, particularly when my mood is low or when I am experiencing difficulties with my mental health.” This remains appropriate and continues to reflect his current level of need. The plan is reviewed as required and updated if there are any changes in his health, dietary needs, or level of independence. RG’s nutritional goals and expected outcomes are clearly defined within his care plan:I want to continue preparing and eating my meals independently while having the freedom to choose the foods I enjoy. I want to maintain a healthy and balanced diet while keeping my cultural food preferences. I would like staff to support me with gentle reminders if needed, particularly if I forget to eat or prepare meals during periods of low mood. I want to stay healthy and maintain my energy levels to support my daily activities without feeling pressured or restricted in my food choices. The nutritional plan was reviewed 14/03/26 | E39: Yes | F39: Green
A40: EFFECTIVE | B40: Nutrition & Health | C40: Special dietary requirements (e.g., cultural, allergies, texture) | D40: RG states in his nutritional care plan: I enjoy cooking Caribbean food, particularly meals that include rice and curries. I sometimes visit my mother to collect meals, and I value this connection with my family as well as the independence it gives me. He has no allergies known which is clearly stated on his Cura profile highlighted red | E40: Yes | F40: Green
...

Sheet Dashboard
A1: Quality Assurance Dashboard
A3: Total Audit Items | B3: =COUNTA('Audit Tool'!C:C)-1 -> 71
A4: Compliant (Yes) | B4: =COUNTIF('Audit Tool'!E:E,"Yes") -> 38
A5: Non-Compliant (No) | B5: =COUNTIF('Audit Tool'!E:E,"No") -> 1
A7: Green | B7: =COUNTIF('Audit Tool'!F:F,"Green") -> 37
A8: Amber | B8: =COUNTIF('Audit Tool'!F:F,"Amber") -> 2
A9: Red | B9: =COUNTIF('Audit Tool'!F:F,"Red") -> 0
A11: % Compliance (Yes / (Yes+No)) | B11: =IFERROR(B4/(B4+B5),0) -> 0.97435897
A13: Compliance by CQC KLOE
A14: KLOE | B14: Yes | C14: No | D14: % Compliance
A15: SAFE | B15: =COUNTIFS('Audit Tool'!A:A,"SAFE",'Audit Tool'!E:E,"Yes") -> 20 | C15: =COUNTIFS('Audit Tool'!A:A,"SAFE",'Audit Tool'!E:E,"No") -> 0 | D15: =IFERROR(B15/(B15+C15),0) -> 1
A16: EFFECTIVE | B16: =COUNTIFS('Audit Tool'!A:A,"EFFECTIVE",'Audit Tool'!E:E,"Yes") -> 2 | C16: =COUNTIFS('Audit Tool'!A:A,"EFFECTIVE",'Audit Tool'!E:E,"No") -> 0 | D16: =IFERROR(B16/(B16+C16),0) -> 1
A17: CARING | B17: =COUNTIFS('Audit Tool'!A:A,"CARING",'Audit Tool'!E:E,"Yes") -> 5 | C17: =COUNTIFS('Audit Tool'!A:A,"CARING",'Audit Tool'!E:E,"No") -> 0 | D17: =IFERROR(B17/(B17+C17),0) -> 1
A18: RESPONSIVE | B18: =COUNTIFS('Audit Tool'!A:A,"RESPONSIVE",'Audit Tool'!E:E,"Yes") -> 0 | C18: =COUNTIFS('Audit Tool'!A:A,"RESPONSIVE",'Audit Tool'!E:E,"No") -> 0 | D18: =IFERROR(B18/(B18+C18),0) -> 0
A19: WELL-LED | B19: =COUNTIFS('Audit Tool'!A:A,"WELL-LED",'Audit Tool'!E:E,"Yes") -> 11 | C19: =COUNTIFS('Audit Tool'!A:A,"WELL-LED",'Audit Tool'!E:E,"No") -> 1 | D19: =IFERROR(B19/(B19+C19),0) -> 0.91666667
